#VRML_SIM R2023b utf8

EXTERNPROTO "https://raw.githubusercontent.com/cyberbotics/webots/R2023b/projects/objects/backgrounds/protos/TexturedBackground.proto"
EXTERNPROTO "https://raw.githubusercontent.com/cyberbotics/webots/R2023b/projects/objects/backgrounds/protos/TexturedBackgroundLight.proto"
EXTERNPROTO "https://raw.githubusercontent.com/cyberbotics/webots/R2023b/projects/objects/floors/protos/RectangleArena.proto"
EXTERNPROTO "https://raw.githubusercontent.com/cyberbotics/webots/R2023b/projects/robots/gctronic/e-puck/protos/E-puck.proto"

WorldInfo {
}
Viewpoint {
  orientation 0.24171618915139434 0.42716457560582993 -0.871265579057051 1.1520068962407615
  position -0.35456222671783194 0.13891668921104172 0.3835085377045421
}
TexturedBackground {
}
TexturedBackgroundLight {
}
RectangleArena {
  floorAppearance Appearance {
    material Material {
    }
    texture ImageTexture {
      url [
        "../elipse.png"
      ]
      repeatS FALSE
      repeatT FALSE
    }
    textureTransform TextureTransform {
      scale 0.5 0.5
    }
  }
}
E-puck {
  translation 0.322484 -0.394135 -6.51419e-05
  rotation 4.521914375770615e-05 1.3829050755546189e-05 -0.9999999988819931 2.6693728725813237
  controller "<none>"
  groundSensorsSlot [
    DistanceSensor {
      translation 0 0.03 0
      rotation 0 1 0 1.5708
      name "ir2left"
      type "infra-red"
    }
    DistanceSensor {
      translation 0 0.02 0
      rotation 0 1 0 1.5708
      name "ir1left"
      type "infra-red"
    }
    DistanceSensor {
      translation 0 0.01 0
      rotation 0 1 0 1.5708
      name "ir0left"
      type "infra-red"
    }
    DistanceSensor {
      translation 0 -0.01 0
      rotation 0 1 0 1.5708
      name "ir0right"
      type "infra-red"
    }
    DistanceSensor {
      translation 0 -0.03 0
      rotation 0 1 0 1.5708
      name "ir2right"
      type "infra-red"
    }
    DistanceSensor {
      translation 0 -0.02 0
      rotation 0 1 0 1.5708
      name "ir1right"
      type "infra-red"
    }
  ]
}
Robot {
  translation 0.0797423 -0.273295 0.02
  rotation 0 0 -1 -3.1415853071795863
  children [
    DEF Sensors Group {
      children [
        DistanceSensor {
          translation 0.07 0.005 -0.0054
          rotation 0 1 0 1.5708
          children [
            Shape {
              appearance PBRAppearance {
                baseColor 1 0 0
                metalness 0
              }
              geometry Box {
                size 0.0005 0.003 0.001
              }
            }
          ]
          name "ir0left"
          type "infra-red"
        }
        DistanceSensor {
          translation 0.07 0.015 -0.0054
          rotation 0 1 0 1.5708
          children [
            Shape {
              appearance PBRAppearance {
                baseColor 1 0 0
                metalness 0
              }
              geometry Box {
                size 0.0005 0.003 0.001
              }
            }
          ]
          name "ir1left"
          type "infra-red"
        }
        DistanceSensor {
          translation 0.07 0.025 -0.0054
          rotation 0 1 0 1.5708
          children [
            Shape {
              appearance PBRAppearance {
                baseColor 1 0 0
                metalness 0
              }
              geometry Box {
                size 0.0005 0.003 0.001
              }
            }
          ]
          name "ir2left"
          type "infra-red"
        }
        DistanceSensor {
          translation 0.07 -0.005 -0.0054
          rotation 0 1 0 1.5708
          children [
            Shape {
              appearance PBRAppearance {
                baseColor 1 0 0
                metalness 0
              }
              geometry Box {
                size 0.0005 0.003 0.001
              }
            }
          ]
          name "ir0right"
          type "infra-red"
        }
        DistanceSensor {
          translation 0.07 -0.015 -0.0054
          rotation 0 1 0 1.5708
          children [
            Shape {
              appearance PBRAppearance {
                baseColor 1 0 0
                metalness 0
              }
              geometry Box {
                size 0.0005 0.003 0.001
              }
            }
          ]
          name "ir1right"
          type "infra-red"
        }
        DistanceSensor {
          translation 0.07 -0.025 -0.0054
          rotation 0 1 0 1.5708
          children [
            Shape {
              appearance PBRAppearance {
                baseColor 1 0 0
                metalness 0
              }
              geometry Box {
                size 0.0005 0.003 0.001
              }
            }
          ]
          name "ir2right"
          type "infra-red"
        }
      ]
    }
    DEF right_wheel HingeJoint {
      jointParameters HingeJointParameters {
        axis 0 1 0
        anchor -0.02 -0.031 -1.01962e-08
      }
      device [
        RotationalMotor {
          name "right wheel motor"
        }
      ]
      endPoint Solid {
        translation -0.02 -0.031 -1.01962e-08
        rotation -0.9999999999999999 0 0 1.5707953071795862
        children [
          DEF wheel1 Shape {
            appearance PBRAppearance {
              baseColor 0 0 0
              metalness 0
            }
            geometry Cylinder {
              height 0.011
              radius 0.014
            }
          }
        ]
        name "solid(1)"
        boundingObject USE wheel1
        physics Physics {
        }
      }
    }
    DEF left_wheel HingeJoint {
      jointParameters HingeJointParameters {
        axis 0 1 0
        anchor -0.02 0.031 -1.01962e-08
      }
      device [
        RotationalMotor {
          name "left wheel motor"
        }
      ]
      endPoint Solid {
        translation -0.02 0.031 -1.01962e-08
        rotation -0.9999999999999999 0 0 1.5707953071795862
        children [
          DEF wheel2 Shape {
            appearance PBRAppearance {
              baseColor 0 0 0
              metalness 0
            }
            geometry Cylinder {
              height 0.011
              radius 0.014
            }
          }
        ]
        name "solid(2)"
        boundingObject USE wheel2
        physics Physics {
        }
      }
    }
    DEF BODY Solid {
      children [
        DEF body Group {
          children [
            Pose {
              translation -0.02 0 0
              children [
                Shape {
                  appearance PBRAppearance {
                  }
                  geometry Box {
                    size 0.03 0.05 0.01
                  }
                }
              ]
            }
            Pose {
              translation 0.01 0 0
              children [
                Shape {
                  appearance PBRAppearance {
                  }
                  geometry Box {
                    size 0.03 0.03 0.01
                  }
                }
              ]
            }
            Pose {
              translation 0.05 0 0
              children [
                Shape {
                  appearance PBRAppearance {
                  }
                  geometry Box {
                    size 0.05 0.01 0.01
                  }
                }
              ]
            }
            Pose {
              translation 0.07 2.03924e-08 -0.004
              rotation 0 0 1 -1.5707953071795862
              children [
                Shape {
                  appearance PBRAppearance {
                  }
                  geometry Box {
                    size 0.06 0.01 0.002
                  }
                }
              ]
            }
            Pose {
              translation 0.06 0 -0.008
              children [
                Shape {
                  appearance PBRAppearance {
                    baseColor 0 0 0
                    metalness 0
                  }
                  geometry Sphere {
                    radius 0.004
                    subdivision 2
                  }
                }
              ]
            }
          ]
        }
      ]
    }
  ]
  boundingObject USE body
  physics Physics {
  }
  controller "line_follower"
}
