#VRML_SIM R2023b utf8

EXTERNPROTO "https://raw.githubusercontent.com/cyberbotics/webots/R2023b/projects/objects/backgrounds/protos/TexturedBackground.proto"
EXTERNPROTO "https://raw.githubusercontent.com/cyberbotics/webots/R2023b/projects/objects/backgrounds/protos/TexturedBackgroundLight.proto"
EXTERNPROTO "https://raw.githubusercontent.com/cyberbotics/webots/R2023b/projects/objects/floors/protos/RectangleArena.proto"
EXTERNPROTO "https://raw.githubusercontent.com/cyberbotics/webots/R2023b/projects/robots/gctronic/e-puck/protos/E-puck.proto"
EXTERNPROTO "https://raw.githubusercontent.com/cyberbotics/webots/R2023b/projects/objects/solids/protos/SolidBox.proto"

WorldInfo {
}
Viewpoint {
  orientation -0.06469555500274593 -0.9124232609688873 0.4041018163851638 5.935794195963497
  position -0.10758013202525835 -0.2816052762936212 0.0515194787889902
}
TexturedBackground {
}
TexturedBackgroundLight {
}
RectangleArena {
  floorAppearance Appearance {
    material Material {
    }
    texture ImageTexture {
      url [
        "../elipse.png"
      ]
      repeatS FALSE
      repeatT FALSE
    }
    textureTransform TextureTransform {
      scale 0.5 0.5
    }
  }
}
SolidBox {
  translation 0.00559949 -0.178 0.01
  rotation 0 0 -1 -5.307179586466759e-06
  size 0.0001 0.04 0.05
}
E-puck {
  hidden position_0_0 1656.9499310762503
  hidden position_0_1 1606.9573560492502
  hidden linearVelocity_0 2.364348992375623e-06 2.1738011995845845e-06 -4.808235268190706e-07
  hidden angularVelocity_0 5.137744207145501e-05 -3.014470274802998e-05 -3.43504978467119e-07
  hidden rotation_1 0 -1 0 1.8109900191605073
  hidden linearVelocity_1 1.884329848067523e-06 1.5632139735544115e-06 5.257409764869436e-07
  hidden angularVelocity_1 5.154860614644467e-05 -3.0189969918244558e-05 -3.5418994225561323e-07
  hidden rotation_2 0 -0.9999999999999999 0 1.5380825887239724
  hidden linearVelocity_2 1.886604469625297e-06 1.5787226463004348e-06 -7.337903193072039e-07
  hidden angularVelocity_2 5.093001496491679e-05 -3.0037890784949025e-05 -3.3261513331196917e-07
  translation -0.46311435221960384 -0.46316204923445103 -4.759231976757955e-05
  rotation -0.0019510611479964543 -0.0010144606660767693 -0.9999975821120538 1.781206877155876
  controller "<none>"
  groundSensorsSlot [
    DistanceSensor {
      translation 0 0.03 0
      rotation 0 1 0 1.5708
      name "ir2left"
      type "infra-red"
    }
    DistanceSensor {
      translation 0 0.02 0
      rotation 0 1 0 1.5708
      name "ir1left"
      type "infra-red"
    }
    DistanceSensor {
      translation 0 0.01 0
      rotation 0 1 0 1.5708
      name "ir0left"
      type "infra-red"
    }
    DistanceSensor {
      translation 0 -0.01 0
      rotation 0 1 0 1.5708
      name "ir0right"
      type "infra-red"
    }
    DistanceSensor {
      translation 0 -0.03 0
      rotation 0 1 0 1.5708
      name "ir2right"
      type "infra-red"
    }
    DistanceSensor {
      translation 0 -0.02 0
      rotation 0 1 0 1.5708
      name "ir1right"
      type "infra-red"
    }
  ]
}
Robot {
  translation 0.026837859621045512 -0.2786145586963842 0.012641339735255264
  rotation -0.033676333734594964 -0.0008660585924141358 0.9994324161686527 -3.0917744407772827
  children [
    DEF Sensors Group {
      children [
        DistanceSensor {
          translation 0.02 0.01 -0.0053998
          rotation 0 1 0 1.5708
          children [
            Shape {
              appearance PBRAppearance {
                baseColor 1 0 0
                metalness 0
              }
              geometry Box {
                size 0.0005 0.003 0.001
              }
            }
          ]
          name "ir0left"
          type "infra-red"
        }
        DistanceSensor {
          translation 0.02 0.02 -0.0053998
          rotation 0 1 0 1.5708
          children [
            Shape {
              appearance PBRAppearance {
                baseColor 1 0 0
                metalness 0
              }
              geometry Box {
                size 0.0005 0.003 0.001
              }
            }
          ]
          name "ir1left"
          type "infra-red"
        }
        DistanceSensor {
          translation 0.02 0.03 -0.0053998
          rotation 0 1 0 1.5708
          children [
            Shape {
              appearance PBRAppearance {
                baseColor 1 0 0
                metalness 0
              }
              geometry Box {
                size 0.0005 0.003 0.001
              }
            }
          ]
          name "ir2left"
          type "infra-red"
        }
        DistanceSensor {
          translation 0.02 -0.01 -0.0053998
          rotation 0 1 0 1.5708
          children [
            Shape {
              appearance PBRAppearance {
                baseColor 1 0 0
                metalness 0
              }
              geometry Box {
                size 0.0005 0.003 0.001
              }
            }
          ]
          name "ir0right"
          type "infra-red"
        }
        DistanceSensor {
          translation 0.02 -0.02 -0.0053998
          rotation 0 1 0 1.5708
          children [
            Shape {
              appearance PBRAppearance {
                baseColor 1 0 0
                metalness 0
              }
              geometry Box {
                size 0.0005 0.003 0.001
              }
            }
          ]
          name "ir1right"
          type "infra-red"
        }
        DistanceSensor {
          translation 0.02 -0.03 -0.0053998
          rotation 0 1 0 1.5708
          children [
            Shape {
              appearance PBRAppearance {
                baseColor 1 0 0
                metalness 0
              }
              geometry Box {
                size 0.0005 0.003 0.001
              }
            }
          ]
          name "ir2right"
          type "infra-red"
        }
      ]
    }
    DEF right_wheel HingeJoint {
      jointParameters HingeJointParameters {
        position 2325.841572486478
        axis 0 1 0
        anchor -0.02 -0.031 -1.01962e-08
      }
      device [
        RotationalMotor {
          name "right wheel motor"
        }
      ]
      endPoint Solid {
        translation -0.019999603122664585 -0.0305 -8.383384022346836e-07
        rotation 0.7689121120395153 -0.45209133061320433 -0.4520924603920244 4.452660232187486
        children [
          DEF wheel1 Shape {
            appearance PBRAppearance {
              baseColor 0 0 0
              metalness 0
            }
            geometry Cylinder {
              height 0.011
              radius 0.014
            }
          }
        ]
        name "solid(1)"
        boundingObject USE wheel1
        physics Physics {
        }
        linearVelocity -0.014329462653125964 -0.0008395320526304833 -6.159744034291e-05
        angularVelocity 0.06603005160913927 -1.0271571511088218 0.011639596458861146
      }
    }
    DEF left_wheel HingeJoint {
      jointParameters HingeJointParameters {
        position 2718.967404998876
        axis 0 1 0
        anchor -0.02 0.031 -1.01962e-08
      }
      device [
        RotationalMotor {
          name "left wheel motor"
        }
      ]
      endPoint Solid {
        translation -0.019998429174639343 0.0305 2.101403726952022e-06
        rotation -0.5461353553265975 -0.5922545452406133 -0.5924278245525996 2.1416979886412615
        children [
          DEF wheel2 Shape {
            appearance PBRAppearance {
              baseColor 0 0 0
              metalness 0
            }
            geometry Cylinder {
              height 0.011
              radius 0.014
            }
          }
        ]
        name "solid(2)"
        boundingObject USE wheel2
        physics Physics {
        }
        linearVelocity -0.01361074555930504 -0.00032234282856021847 -6.441632145299453e-05
        angularVelocity 0.02277368352632242 -0.9667214009939622 0.010363877092862017
      }
    }
    DEF BODY Solid {
      children [
        DEF body Group {
          children [
            Pose {
              translation -0.02 0 0
              children [
                Shape {
                  appearance PBRAppearance {
                  }
                  geometry Box {
                    size 0.02 0.05 0.01
                  }
                }
              ]
            }
            Pose {
              children [
                Shape {
                  appearance PBRAppearance {
                  }
                  geometry Box {
                    size 0.02 0.03 0.01
                  }
                }
              ]
            }
            Pose {
              translation 0.015 0 0
              children [
                Shape {
                  appearance PBRAppearance {
                  }
                  geometry Box {
                    size 0.02 0.01 0.01
                  }
                }
              ]
            }
            Pose {
              translation 0.02 2.03924e-08 -0.004
              rotation 0 0 1 -1.5707953071795862
              children [
                Shape {
                  appearance PBRAppearance {
                  }
                  geometry Box {
                    size 0.075 0.01 0.002
                  }
                }
              ]
            }
            Pose {
              translation 0.01 0 -0.008
              children [
                Shape {
                  appearance PBRAppearance {
                    baseColor 0 0 0
                    metalness 0
                  }
                  geometry Sphere {
                    radius 0.004
                    subdivision 2
                  }
                }
              ]
            }
          ]
        }
      ]
    }
  ]
  boundingObject USE body
  physics Physics {
  }
  controller "line_follower"
  linearVelocity -0.013860856951643297 -0.0007344667495013148 -3.483955019542121e-05
  angularVelocity -8.586657755125737e-05 0.00208283165175873 0.012429093902374122
}
