#VRML_SIM R2023b utf8

EXTERNPROTO "https://raw.githubusercontent.com/cyberbotics/webots/R2023b/projects/objects/backgrounds/protos/TexturedBackground.proto"
EXTERNPROTO "https://raw.githubusercontent.com/cyberbotics/webots/R2023b/projects/objects/backgrounds/protos/TexturedBackgroundLight.proto"
EXTERNPROTO "https://raw.githubusercontent.com/cyberbotics/webots/R2023b/projects/objects/floors/protos/RectangleArena.proto"
EXTERNPROTO "https://raw.githubusercontent.com/cyberbotics/webots/R2023b/projects/robots/gctronic/e-puck/protos/E-puck.proto"

WorldInfo {
}
Viewpoint {
  orientation -0.410218269921234 -0.5819956274341336 0.7021410546823044 4.70854157833173
  position -0.3477472242821281 0.633836986279376 1.5730506757797937
}
TexturedBackground {
}
TexturedBackgroundLight {
}
RectangleArena {
  floorAppearance Appearance {
    material Material {
    }
    texture ImageTexture {
      url [
        "../pista1.png"
      ]
      repeatS FALSE
      repeatT FALSE
    }
    textureTransform TextureTransform {
      scale 0.5 0.5
    }
  }
}
E-puck {
  translation -0.4631765093694154 -0.4632357774251278 -3.6099195311707286e-05
  rotation -0.002798471959163859 -0.0013726990084096998 -0.9999951421142634 1.7805493231070237
  controller "<none>"
  groundSensorsSlot [
    DistanceSensor {
      translation 0 0.03 0
      rotation 0 1 0 1.5708
      name "ir2left"
      type "infra-red"
    }
    DistanceSensor {
      translation 0 0.02 0
      rotation 0 1 0 1.5708
      name "ir1left"
      type "infra-red"
    }
    DistanceSensor {
      translation 0 0.01 0
      rotation 0 1 0 1.5708
      name "ir0left"
      type "infra-red"
    }
    DistanceSensor {
      translation 0 -0.01 0
      rotation 0 1 0 1.5708
      name "ir0right"
      type "infra-red"
    }
    DistanceSensor {
      translation 0 -0.03 0
      rotation 0 1 0 1.5708
      name "ir2right"
      type "infra-red"
    }
    DistanceSensor {
      translation 0 -0.02 0
      rotation 0 1 0 1.5708
      name "ir1right"
      type "infra-red"
    }
  ]
}
Robot {
  translation -0.149716 -0.285737 0.017356
  rotation 0.0337003442022856 -0.005563246336841158 -0.9994164983083095 -2.813376248638155
  children [
    DEF Sensors Group {
      children [
        DistanceSensor {
          translation 0.02 0.01 -0.0053998
          rotation 0 1 0 1.5708
          children [
            Shape {
              appearance PBRAppearance {
                baseColor 1 0 0
                metalness 0
              }
              geometry Box {
                size 0.0005 0.003 0.001
              }
            }
          ]
          name "ir0left"
          type "infra-red"
        }
        DistanceSensor {
          translation 0.02 0.02 -0.0053998
          rotation 0 1 0 1.5708
          children [
            Shape {
              appearance PBRAppearance {
                baseColor 1 0 0
                metalness 0
              }
              geometry Box {
                size 0.0005 0.003 0.001
              }
            }
          ]
          name "ir1left"
          type "infra-red"
        }
        DistanceSensor {
          translation 0.02 0.03 -0.0053998
          rotation 0 1 0 1.5708
          children [
            Shape {
              appearance PBRAppearance {
                baseColor 1 0 0
                metalness 0
              }
              geometry Box {
                size 0.0005 0.003 0.001
              }
            }
          ]
          name "ir2left"
          type "infra-red"
        }
        DistanceSensor {
          translation 0.02 -0.01 -0.0053998
          rotation 0 1 0 1.5708
          children [
            Shape {
              appearance PBRAppearance {
                baseColor 1 0 0
                metalness 0
              }
              geometry Box {
                size 0.0005 0.003 0.001
              }
            }
          ]
          name "ir0right"
          type "infra-red"
        }
        DistanceSensor {
          translation 0.02 -0.02 -0.0053998
          rotation 0 1 0 1.5708
          children [
            Shape {
              appearance PBRAppearance {
                baseColor 1 0 0
                metalness 0
              }
              geometry Box {
                size 0.0005 0.003 0.001
              }
            }
          ]
          name "ir1right"
          type "infra-red"
        }
        DistanceSensor {
          translation 0.02 -0.03 -0.0053998
          rotation 0 1 0 1.5708
          children [
            Shape {
              appearance PBRAppearance {
                baseColor 1 0 0
                metalness 0
              }
              geometry Box {
                size 0.0005 0.003 0.001
              }
            }
          ]
          name "ir2right"
          type "infra-red"
        }
      ]
    }
    DEF right_wheel HingeJoint {
      jointParameters HingeJointParameters {
        position 2035.2473410538091
        axis 0 1 0
        anchor -0.02 -0.031 -1.01962e-08
      }
      device [
        RotationalMotor {
          name "right wheel motor"
          maxVelocity 100
        }
      ]
      endPoint Solid {
        translation -0.01999917063578704 -0.0305 3.8412109451245046e-07
        rotation 0.939484767729701 0.24227208108418014 0.24222429673963386 4.650054878896689
        children [
          DEF wheel1 Shape {
            appearance PBRAppearance {
              baseColor 0 0 0
              metalness 0
            }
            geometry Cylinder {
              height 0.011
              radius 0.014
            }
          }
        ]
        name "solid(1)"
        boundingObject USE wheel1
        physics Physics {
        }
      }
    }
    DEF left_wheel HingeJoint {
      jointParameters HingeJointParameters {
        position 2360.308088074732
        axis 0 1 0
        anchor -0.02 0.031 -1.01962e-08
      }
      device [
        RotationalMotor {
          name "left wheel motor"
          maxVelocity 100
        }
      ]
      endPoint Solid {
        translation -0.01999968015277221 0.0305 2.602090981011137e-06
        rotation 0.34986647715069796 0.6623512092249538 0.6624834517211746 3.8149360235396643
        children [
          DEF wheel2 Shape {
            appearance PBRAppearance {
              baseColor 0 0 0
              metalness 0
            }
            geometry Cylinder {
              height 0.011
              radius 0.014
            }
          }
        ]
        name "solid(2)"
        boundingObject USE wheel2
        physics Physics {
        }
      }
    }
    DEF BODY Solid {
      children [
        DEF body Group {
          children [
            Pose {
              translation -0.02 0 0
              children [
                Shape {
                  appearance PBRAppearance {
                  }
                  geometry Box {
                    size 0.02 0.05 0.01
                  }
                }
              ]
            }
            Pose {
              children [
                Shape {
                  appearance PBRAppearance {
                  }
                  geometry Box {
                    size 0.02 0.03 0.01
                  }
                }
              ]
            }
            Pose {
              translation 0.015 0 0
              children [
                Shape {
                  appearance PBRAppearance {
                  }
                  geometry Box {
                    size 0.02 0.01 0.01
                  }
                }
              ]
            }
            Pose {
              translation 0.02 2.03924e-08 -0.004
              rotation 0 0 1 -1.5707953071795862
              children [
                Shape {
                  appearance PBRAppearance {
                  }
                  geometry Box {
                    size 0.075 0.01 0.002
                  }
                }
              ]
            }
            Pose {
              translation 0.01 0 -0.008
              children [
                Shape {
                  appearance PBRAppearance {
                    baseColor 0 0 0
                    metalness 0
                  }
                  geometry Sphere {
                    radius 0.004
                    subdivision 2
                  }
                }
              ]
            }
          ]
        }
      ]
    }
  ]
  boundingObject USE body
  physics Physics {
  }
  controller "line_follower"
}
